Traceback (most recent call last):
  File "/usr/local/lib/python3.8/dist-packages/sqlalchemy/engine/base.py", line 146, in __init__
    self._dbapi_connection = engine.raw_connection()
  File "/usr/local/lib/python3.8/dist-packages/sqlalchemy/engine/base.py", line 3304, in raw_connection
    return self.pool.connect()
  File "/usr/local/lib/python3.8/dist-packages/sqlalchemy/pool/base.py", line 449, in connect
    return _ConnectionFairy._checkout(self)
  File "/usr/local/lib/python3.8/dist-packages/sqlalchemy/pool/base.py", line 1263, in _checkout
    fairy = _ConnectionRecord.checkout(pool)
  File "/usr/local/lib/python3.8/dist-packages/sqlalchemy/pool/base.py", line 712, in checkout
    rec = pool._do_get()
  File "/usr/local/lib/python3.8/dist-packages/sqlalchemy/pool/impl.py", line 180, in _do_get
    self._dec_overflow()
  File "/usr/local/lib/python3.8/dist-packages/sqlalchemy/util/langhelpers.py", line 146, in __exit__
    raise exc_value.with_traceback(exc_tb)
  File "/usr/local/lib/python3.8/dist-packages/sqlalchemy/pool/impl.py", line 177, in _do_get
    return self._create_connection()
  File "/usr/local/lib/python3.8/dist-packages/sqlalchemy/pool/base.py", line 390, in _create_connection
    return _ConnectionRecord(self)
  File "/usr/local/lib/python3.8/dist-packages/sqlalchemy/pool/base.py", line 674, in __init__
    self.__connect()
  File "/usr/local/lib/python3.8/dist-packages/sqlalchemy/pool/base.py", line 901, in __connect
    pool.logger.debug("Error on connect(): %s", e)
  File "/usr/local/lib/python3.8/dist-packages/sqlalchemy/util/langhelpers.py", line 146, in __exit__
    raise exc_value.with_traceback(exc_tb)
  File "/usr/local/lib/python3.8/dist-packages/sqlalchemy/pool/base.py", line 896, in __connect
    self.dbapi_connection = connection = pool._invoke_creator(self)
  File "/usr/local/lib/python3.8/dist-packages/sqlalchemy/engine/create.py", line 643, in connect
    return dialect.connect(*cargs, **cparams)
  File "/usr/local/lib/python3.8/dist-packages/sqlalchemy/engine/default.py", line 617, in connect
    return self.loaded_dbapi.connect(*cargs, **cparams)
  File "/usr/local/lib/python3.8/dist-packages/MySQLdb/__init__.py", line 121, in Connect
    return Connection(*args, **kwargs)
  File "/usr/local/lib/python3.8/dist-packages/MySQLdb/connections.py", line 195, in __init__
    super().__init__(*args, **kwargs2)
MySQLdb.OperationalError: (2002, "Can't connect to local MySQL server through socket '/var/run/mysqld/mysqld.sock' (111)")

The above exception was the direct cause of the following exception:

Traceback (most recent call last):
  File "/usr/lib/python3.8/runpy.py", line 194, in _run_module_as_main
    return _run_code(code, main_globals, None,
  File "/usr/lib/python3.8/runpy.py", line 87, in _run_code
    exec(code, run_globals)
  File "/portfolio_project/Connected_Care/hie_flask/app.py", line 3, in <module>
    from hie_models import storage
  File "/portfolio_project/Connected_Care/hie_models/__init__.py", line 10, in <module>
    storage.reload()
  File "/portfolio_project/Connected_Care/hie_models/hie_db/db_storage.py", line 89, in reload
    Base.metadata.create_all(self.__engine)
  File "/usr/local/lib/python3.8/dist-packages/sqlalchemy/sql/schema.py", line 5825, in create_all
    bind._run_ddl_visitor(
  File "/usr/local/lib/python3.8/dist-packages/sqlalchemy/engine/base.py", line 3254, in _run_ddl_visitor
    with self.begin() as conn:
  File "/usr/lib/python3.8/contextlib.py", line 113, in __enter__
    return next(self.gen)
  File "/usr/local/lib/python3.8/dist-packages/sqlalchemy/engine/base.py", line 3244, in begin
    with self.connect() as conn:
  File "/usr/local/lib/python3.8/dist-packages/sqlalchemy/engine/base.py", line 3280, in connect
    return self._connection_cls(self)
  File "/usr/local/lib/python3.8/dist-packages/sqlalchemy/engine/base.py", line 148, in __init__
    Connection._handle_dbapi_exception_noconnection(
  File "/usr/local/lib/python3.8/dist-packages/sqlalchemy/engine/base.py", line 2444, in _handle_dbapi_exception_noconnection
    raise sqlalchemy_exception.with_traceback(exc_info[2]) from e
  File "/usr/local/lib/python3.8/dist-packages/sqlalchemy/engine/base.py", line 146, in __init__
    self._dbapi_connection = engine.raw_connection()
  File "/usr/local/lib/python3.8/dist-packages/sqlalchemy/engine/base.py", line 3304, in raw_connection
    return self.pool.connect()
  File "/usr/local/lib/python3.8/dist-packages/sqlalchemy/pool/base.py", line 449, in connect
    return _ConnectionFairy._checkout(self)
  File "/usr/local/lib/python3.8/dist-packages/sqlalchemy/pool/base.py", line 1263, in _checkout
    fairy = _ConnectionRecord.checkout(pool)
  File "/usr/local/lib/python3.8/dist-packages/sqlalchemy/pool/base.py", line 712, in checkout
    rec = pool._do_get()
  File "/usr/local/lib/python3.8/dist-packages/sqlalchemy/pool/impl.py", line 180, in _do_get
    self._dec_overflow()
  File "/usr/local/lib/python3.8/dist-packages/sqlalchemy/util/langhelpers.py", line 146, in __exit__
    raise exc_value.with_traceback(exc_tb)
  File "/usr/local/lib/python3.8/dist-packages/sqlalchemy/pool/impl.py", line 177, in _do_get
    return self._create_connection()
  File "/usr/local/lib/python3.8/dist-packages/sqlalchemy/pool/base.py", line 390, in _create_connection
    return _ConnectionRecord(self)
  File "/usr/local/lib/python3.8/dist-packages/sqlalchemy/pool/base.py", line 674, in __init__
    self.__connect()
  File "/usr/local/lib/python3.8/dist-packages/sqlalchemy/pool/base.py", line 901, in __connect
    pool.logger.debug("Error on connect(): %s", e)
  File "/usr/local/lib/python3.8/dist-packages/sqlalchemy/util/langhelpers.py", line 146, in __exit__
    raise exc_value.with_traceback(exc_tb)
  File "/usr/local/lib/python3.8/dist-packages/sqlalchemy/pool/base.py", line 896, in __connect
    self.dbapi_connection = connection = pool._invoke_creator(self)
  File "/usr/local/lib/python3.8/dist-packages/sqlalchemy/engine/create.py", line 643, in connect
    return dialect.connect(*cargs, **cparams)
  File "/usr/local/lib/python3.8/dist-packages/sqlalchemy/engine/default.py", line 617, in connect
    return self.loaded_dbapi.connect(*cargs, **cparams)
  File "/usr/local/lib/python3.8/dist-packages/MySQLdb/__init__.py", line 121, in Connect
    return Connection(*args, **kwargs)
  File "/usr/local/lib/python3.8/dist-packages/MySQLdb/connections.py", line 195, in __init__
    super().__init__(*args, **kwargs2)
sqlalchemy.exc.OperationalError: (MySQLdb.OperationalError) (2002, "Can't connect to local MySQL server through socket '/var/run/mysqld/mysqld.sock' (111)")
(Background on this error at: https://sqlalche.me/e/20/e3q8)
